<?xml version="1.0" ?>
<robot name="spot_mini_3">

<material name="silver">
  <color rgba="0.700 0.700 0.700 1.000"/>
</material>

<link name="base_link">
  <inertial>
    <origin xyz="0.15055773216211757 0.1546306649325129 0.4145956403783646" rpy="0 0 0"/>
    <mass value="1.5"/>
    <inertia ixx="0.007855785006969873" iyy="0.0010119233592134347" izz="0.00812257204073424" ixy="4.931740771303358e-06" iyz="-7.559534854537087e-05" ixz="-8.42877370531292e-07"/>
  </inertial>
  <visual>
    <origin xyz="0 0 0" rpy="0 0 0"/>
    <geometry>
      <mesh filename="meshes/base_link.stl" scale="0.001 0.001 0.001"/>
    </geometry>
    <material name="silver"/>
    <material/>
  </visual>
  <collision>
    <origin xyz="0 0 0" rpy="0 0 0"/>
    <geometry>
      <mesh filename="meshes/base_link.stl" scale="0.001 0.001 0.001"/>
    </geometry>
  </collision>
</link>

<link name="FL_Arm_11FL_shoulder1">
  <inertial>
    <origin xyz="-0.01226341546823101 0.023797965913628122 -0.01047848981209304" rpy="0 0 0"/>
    <mass value="0.0010460322298815623"/>
    <inertia ixx="4.5894426660159776e-07" iyy="3.9412489574998876e-07" izz="2.4792830692763805e-07" ixy="2.3383310631803865e-08" iyz="1.0697598474640555e-09" ixz="2.6589199819768844e-09"/>
  </inertial>
  <visual>
    <origin xyz="-0.111622 -0.218934 -0.418766" rpy="0 0 0"/>
    <geometry>
      <mesh filename="meshes/FL_Arm_11FL_shoulder1.stl" scale="0.001 0.001 0.001"/>
    </geometry>
    <material name="silver"/>
    <material/>
  </visual>
  <collision>
    <origin xyz="-0.111622 -0.218934 -0.418766" rpy="0 0 0"/>
    <geometry>
      <mesh filename="meshes/FL_Arm_11FL_shoulder1.stl" scale="0.001 0.001 0.001"/>
    </geometry>
  </collision>
</link>

<link name="FR_Arm1FR_shoulder1">
  <inertial>
    <origin xyz="0.01226272266518752 0.023797965913627983 -0.010478492514241933" rpy="0 0 0"/>
    <mass value="0.0010460322298815618"/>
    <inertia ixx="4.5894426660159776e-07" iyy="3.9412489574990744e-07" izz="2.479283069276245e-07" ixy="-2.338331063181403e-08" iyz="1.0697598474640555e-09" ixz="-2.6589199819768844e-09"/>
  </inertial>
  <visual>
    <origin xyz="-0.189622 -0.218934 -0.418766" rpy="0 0 0"/>
    <geometry>
      <mesh filename="meshes/FR_Arm1FR_shoulder1.stl" scale="0.001 0.001 0.001"/>
    </geometry>
    <material name="silver"/>
    <material/>
  </visual>
  <collision>
    <origin xyz="-0.189622 -0.218934 -0.418766" rpy="0 0 0"/>
    <geometry>
      <mesh filename="meshes/FR_Arm1FR_shoulder1.stl" scale="0.001 0.001 0.001"/>
    </geometry>
  </collision>
</link>

<link name="BL_Arm1BL_shoulder1">
  <inertial>
    <origin xyz="-0.012263291259574427 0.02154805695734561 -0.010479404940207604" rpy="0 0 0"/>
    <mass value="0.0010460322298815623"/>
    <inertia ixx="4.5894426660165197e-07" iyy="3.9412489575001586e-07" izz="2.479283069276177e-07" ixy="2.3383310631803865e-08" iyz="1.0697598474572793e-09" ixz="2.6589199819768844e-09"/>
  </inertial>
  <visual>
    <origin xyz="-0.111622 -0.038434 -0.418767" rpy="0 0 0"/>
    <geometry>
      <mesh filename="meshes/BL_Arm1BL_shoulder1.stl" scale="0.001 0.001 0.001"/>
    </geometry>
    <material name="silver"/>
    <material/>
  </visual>
  <collision>
    <origin xyz="-0.111622 -0.038434 -0.418767" rpy="0 0 0"/>
    <geometry>
      <mesh filename="meshes/BL_Arm1BL_shoulder1.stl" scale="0.001 0.001 0.001"/>
    </geometry>
  </collision>
</link>

<link name="BR_Arm1BR_shoulder1">
  <inertial>
    <origin xyz="0.012262846873844435 0.021548056957345726 -0.01047940764235411" rpy="0 0 0"/>
    <mass value="0.0010460322298815618"/>
    <inertia ixx="4.5894426660162487e-07" iyy="3.9412489574998876e-07" izz="2.479283069276177e-07" ixy="-2.338331063180217e-08" iyz="1.0697598474674436e-09" ixz="-2.658919981990437e-09"/>
  </inertial>
  <visual>
    <origin xyz="-0.189622 -0.038434 -0.418767" rpy="0 0 0"/>
    <geometry>
      <mesh filename="meshes/BR_Arm1BR_shoulder1.stl" scale="0.001 0.001 0.001"/>
    </geometry>
    <material name="silver"/>
    <material/>
  </visual>
  <collision>
    <origin xyz="-0.189622 -0.038434 -0.418767" rpy="0 0 0"/>
    <geometry>
      <mesh filename="meshes/BR_Arm1BR_shoulder1.stl" scale="0.001 0.001 0.001"/>
    </geometry>
  </collision>
</link>

<link name="FL_Arm_11FL_Upper_Leg1">
  <inertial>
    <origin xyz="-0.01800811022483563 -0.011112728510592251 -0.014773561322106554" rpy="0 0 0"/>
    <mass value="0.0035863240208185553"/>
    <inertia ixx="4.407468997596185e-06" iyy="2.68431105878179e-06" izz="2.847838497458202e-06" ixy="-1.235396651983107e-08" iyz="-1.9578915731026402e-06" ixz="-8.752157331336219e-09"/>
  </inertial>
  <visual>
    <origin xyz="-0.069356 -0.223247 -0.386579" rpy="0 0 0"/>
    <geometry>
      <mesh filename="meshes/FL_Arm_11FL_Upper_Leg1.stl" scale="0.001 0.001 0.001"/>
    </geometry>
    <material name="silver"/>
    <material/>
  </visual>
  <collision>
    <origin xyz="-0.069356 -0.223247 -0.386579" rpy="0 0 0"/>
    <geometry>
      <mesh filename="meshes/FL_Arm_11FL_Upper_Leg1.stl" scale="0.001 0.001 0.001"/>
    </geometry>
  </collision>
</link>

<link name="FL_Arm_11FL_motor1">
  <inertial>
    <origin xyz="-0.02803534463866813 -0.007018715988031665 -0.007018198166182044" rpy="0 0 0"/>
    <mass value="0.08567670259846816"/>
    <inertia ixx="1.4918093587314163e-05" iyy="1.8254630334708574e-05" izz="1.8254629313898402e-05" ixy="-3.2162770326454176e-07" iyz="-4.640045534682127e-06" ixz="-3.216275840200837e-07"/>
  </inertial>
  <visual>
    <origin xyz="-0.090322 -0.244689 -0.408021" rpy="0 0 0"/>
    <geometry>
      <mesh filename="meshes/FL_Arm_11FL_motor1.stl" scale="0.001 0.001 0.001"/>
    </geometry>
    <material name="silver"/>
    <material/>
  </visual>
  <collision>
    <origin xyz="-0.090322 -0.244689 -0.408021" rpy="0 0 0"/>
    <geometry>
      <mesh filename="meshes/FL_Arm_11FL_motor1.stl" scale="0.001 0.001 0.001"/>
    </geometry>
  </collision>
</link>

<link name="FL_Arm_11FL_Foot1">
  <inertial>
    <origin xyz="0.010005471260456554 0.004552095230761277 -0.008934825902760207" rpy="0 0 0"/>
    <mass value="0.003237400185672279"/>
    <inertia ixx="5.216745834557904e-07" iyy="2.3994666300297435e-07" izz="4.5003731953156345e-07" ixy="4.0127948336963256e-10" iyz="-1.3731836157228209e-07" ixz="1.360930547536542e-10"/>
  </inertial>
  <visual>
    <origin xyz="-0.044152 -0.262021 -0.24057" rpy="0 0 0"/>
    <geometry>
      <mesh filename="meshes/FL_Arm_11FL_Foot1.stl" scale="0.001 0.001 0.001"/>
    </geometry>
    <material name="silver"/>
    <material/>
  </visual>
  <collision>
    <origin xyz="-0.044152 -0.262021 -0.24057" rpy="0 0 0"/>
    <geometry>
      <mesh filename="meshes/FL_Arm_11FL_Foot1.stl" scale="0.001 0.001 0.001"/>
    </geometry>
  </collision>
</link>

<link name="FL_Arm_11FL_lower_Leg1">
  <inertial>
    <origin xyz="0.02406399499544222 0.03648480959383599 -0.03746448422327797" rpy="0 0 0"/>
    <mass value="0.0012931113059198964"/>
    <inertia ixx="3.034781363453037e-06" iyy="1.3897431509676941e-06" izz="1.8233444936489792e-06" ixy="-1.147149831584017e-07" iyz="1.4079004592485014e-06" ixz="9.205990545020401e-08"/>
  </inertial>
  <visual>
    <origin xyz="-0.027254 -0.178487 -0.321776" rpy="0 0 0"/>
    <geometry>
      <mesh filename="meshes/FL_Arm_11FL_lower_Leg1.stl" scale="0.001 0.001 0.001"/>
    </geometry>
    <material name="silver"/>
    <material/>
  </visual>
  <collision>
    <origin xyz="-0.027254 -0.178487 -0.321776" rpy="0 0 0"/>
    <geometry>
      <mesh filename="meshes/FL_Arm_11FL_lower_Leg1.stl" scale="0.001 0.001 0.001"/>
    </geometry>
  </collision>
</link>

<link name="BL_Arm1BL_Foot1">
  <inertial>
    <origin xyz="0.010005595469113282 0.004552186274480299 -0.008934741030875215" rpy="0 0 0"/>
    <mass value="0.003237400185672279"/>
    <inertia ixx="5.216745834555735e-07" iyy="2.399466630031099e-07" izz="4.500373195315228e-07" ixy="4.0127948339504355e-10" iyz="-1.3731836157224143e-07" ixz="1.3609305474687793e-10"/>
  </inertial>
  <visual>
    <origin xyz="-0.044152 -0.079271 -0.24057" rpy="0 0 0"/>
    <geometry>
      <mesh filename="meshes/BL_Arm1BL_Foot1.stl" scale="0.001 0.001 0.001"/>
    </geometry>
    <material name="silver"/>
    <material/>
  </visual>
  <collision>
    <origin xyz="-0.044152 -0.079271 -0.24057" rpy="0 0 0"/>
    <geometry>
      <mesh filename="meshes/BL_Arm1BL_Foot1.stl" scale="0.001 0.001 0.001"/>
    </geometry>
  </collision>
</link>

<link name="BL_Arm1BL_lower_Leg_1">
  <inertial>
    <origin xyz="0.024064119204098594 0.03648490063755493 -0.03746439935139362" rpy="0 0 0"/>
    <mass value="0.0012931113059198964"/>
    <inertia ixx="3.0347813634531453e-06" iyy="1.3897431509678974e-06" izz="1.823344493648814e-06" ixy="-1.1471498315836485e-07" iyz="1.4079004592484743e-06" ixz="9.205990545024467e-08"/>
  </inertial>
  <visual>
    <origin xyz="-0.027254 0.004263 -0.321776" rpy="0 0 0"/>
    <geometry>
      <mesh filename="meshes/BL_Arm1BL_lower_Leg_1.stl" scale="0.001 0.001 0.001"/>
    </geometry>
    <material name="silver"/>
    <material/>
  </visual>
  <collision>
    <origin xyz="-0.027254 0.004263 -0.321776" rpy="0 0 0"/>
    <geometry>
      <mesh filename="meshes/BL_Arm1BL_lower_Leg_1.stl" scale="0.001 0.001 0.001"/>
    </geometry>
  </collision>
</link>

<link name="BL_Arm1BL_Upper_Leg1">
  <inertial>
    <origin xyz="-0.01800898601617898 -0.011112637466874527 -0.014773476450221923" rpy="0 0 0"/>
    <mass value="0.0035863240208185553"/>
    <inertia ixx="4.407468997596293e-06" iyy="2.684311058782549e-06" izz="2.847838497457841e-06" ixy="-1.2353966519835305e-08" iyz="-1.9578915731024166e-06" ixz="-8.752157331309114e-09"/>
  </inertial>
  <visual>
    <origin xyz="-0.069357 -0.040497 -0.386579" rpy="0 0 0"/>
    <geometry>
      <mesh filename="meshes/BL_Arm1BL_Upper_Leg1.stl" scale="0.001 0.001 0.001"/>
    </geometry>
    <material name="silver"/>
    <material/>
  </visual>
  <collision>
    <origin xyz="-0.069357 -0.040497 -0.386579" rpy="0 0 0"/>
    <geometry>
      <mesh filename="meshes/BL_Arm1BL_Upper_Leg1.stl" scale="0.001 0.001 0.001"/>
    </geometry>
  </collision>
</link>

<link name="BL_Arm1BL_motor1">
  <inertial>
    <origin xyz="-0.028035220430011512 -0.007018624944314121 -0.007019113294296497" rpy="0 0 0"/>
    <mass value="0.08567670259846816"/>
    <inertia ixx="1.4918093587310693e-05" iyy="1.825463033470684e-05" izz="1.825462931389775e-05" ixy="-3.216277032642707e-07" iyz="-4.640045534682344e-06" ixz="-3.216275840200837e-07"/>
  </inertial>
  <visual>
    <origin xyz="-0.090322 -0.061939 -0.408022" rpy="0 0 0"/>
    <geometry>
      <mesh filename="meshes/BL_Arm1BL_motor1.stl" scale="0.001 0.001 0.001"/>
    </geometry>
    <material name="silver"/>
    <material/>
  </visual>
  <collision>
    <origin xyz="-0.090322 -0.061939 -0.408022" rpy="0 0 0"/>
    <geometry>
      <mesh filename="meshes/BL_Arm1BL_motor1.stl" scale="0.001 0.001 0.001"/>
    </geometry>
  </collision>
</link>

<link name="FR_Arm1FR_motor1">
  <inertial>
    <origin xyz="0.028035177551856305 -0.007018715817410703 -0.007018200687619824" rpy="0 0 0"/>
    <mass value="0.08567670473779747"/>
    <inertia ixx="1.4918093914139535e-05" iyy="1.8254631175378122e-05" izz="1.825463017092986e-05" ixy="3.216273783629778e-07" iyz="-4.640045682827512e-06" ixz="3.2162727459442153e-07"/>
  </inertial>
  <visual>
    <origin xyz="-0.210921 -0.244689 -0.408021" rpy="0 0 0"/>
    <geometry>
      <mesh filename="meshes/FR_Arm1FR_motor1.stl" scale="0.001 0.001 0.001"/>
    </geometry>
    <material name="silver"/>
    <material/>
  </visual>
  <collision>
    <origin xyz="-0.210921 -0.244689 -0.408021" rpy="0 0 0"/>
    <geometry>
      <mesh filename="meshes/FR_Arm1FR_motor1.stl" scale="0.001 0.001 0.001"/>
    </geometry>
  </collision>
</link>

<link name="FR_Arm1FR_Foot1">
  <inertial>
    <origin xyz="-0.01000301599464648 0.004552296630410901 -0.008935514192143057" rpy="0 0 0"/>
    <mass value="0.0032370800830491702"/>
    <inertia ixx="5.215637352757089e-07" iyy="2.398877784611192e-07" izz="4.4996323747634875e-07" ixy="-3.202765609959437e-10" iyz="-1.3730099257240765e-07" ixz="-1.8271967654735245e-10"/>
  </inertial>
  <visual>
    <origin xyz="-0.257091 -0.262021 -0.24057" rpy="0 0 0"/>
    <geometry>
      <mesh filename="meshes/FR_Arm1FR_Foot1.stl" scale="0.001 0.001 0.001"/>
    </geometry>
    <material name="silver"/>
    <material/>
  </visual>
  <collision>
    <origin xyz="-0.257091 -0.262021 -0.24057" rpy="0 0 0"/>
    <geometry>
      <mesh filename="meshes/FR_Arm1FR_Foot1.stl" scale="0.001 0.001 0.001"/>
    </geometry>
  </collision>
</link>

<link name="FR_Arm1FR_lower_Leg1">
  <inertial>
    <origin xyz="-0.02406416163530381 0.03648480997630493 -0.037464486542955866" rpy="0 0 0"/>
    <mass value="0.0012931113059199838"/>
    <inertia ixx="3.0347813634531453e-06" iyy="1.3897431509674366e-06" izz="1.8233444936496433e-06" ixy="1.1471498315821535e-07" iyz="1.4079004592482982e-06" ixz="-9.205990545007865e-08"/>
  </inertial>
  <visual>
    <origin xyz="-0.273989 -0.178487 -0.321776" rpy="0 0 0"/>
    <geometry>
      <mesh filename="meshes/FR_Arm1FR_lower_Leg1.stl" scale="0.001 0.001 0.001"/>
    </geometry>
    <material name="silver"/>
    <material/>
  </visual>
  <collision>
    <origin xyz="-0.273989 -0.178487 -0.321776" rpy="0 0 0"/>
    <geometry>
      <mesh filename="meshes/FR_Arm1FR_lower_Leg1.stl" scale="0.001 0.001 0.001"/>
    </geometry>
  </collision>
</link>

<link name="FR_Arm1FR_Upper_Leg1">
  <inertial>
    <origin xyz="0.018008925063041553 -0.011112696813045164 -0.014773497523763668" rpy="0 0 0"/>
    <mass value="0.0035863185548493546"/>
    <inertia ixx="4.407454092536793e-06" iyy="2.6842975551357806e-06" izz="2.8478344159721847e-06" ixy="1.2353075981835077e-08" iyz="-1.95788646826031e-06" ixz="8.749586127777993e-09"/>
  </inertial>
  <visual>
    <origin xyz="-0.231886 -0.223247 -0.386579" rpy="0 0 0"/>
    <geometry>
      <mesh filename="meshes/FR_Arm1FR_Upper_Leg1.stl" scale="0.001 0.001 0.001"/>
    </geometry>
    <material name="silver"/>
    <material/>
  </visual>
  <collision>
    <origin xyz="-0.231886 -0.223247 -0.386579" rpy="0 0 0"/>
    <geometry>
      <mesh filename="meshes/FR_Arm1FR_Upper_Leg1.stl" scale="0.001 0.001 0.001"/>
    </geometry>
  </collision>
</link>

<link name="BR_Arm1BR_motor1">
  <inertial>
    <origin xyz="0.028035301760513387 -0.007018624773692916 -0.00701911581573178" rpy="0 0 0"/>
    <mass value="0.08567670473779747"/>
    <inertia ixx="1.4918093914136066e-05" iyy="1.825463117538159e-05" izz="1.825463017093073e-05" ixy="3.216273783631946e-07" iyz="-4.640045682824693e-06" ixz="3.2162727459442153e-07"/>
  </inertial>
  <visual>
    <origin xyz="-0.210921 -0.061939 -0.408022" rpy="0 0 0"/>
    <geometry>
      <mesh filename="meshes/BR_Arm1BR_motor1.stl" scale="0.001 0.001 0.001"/>
    </geometry>
    <material name="silver"/>
    <material/>
  </visual>
  <collision>
    <origin xyz="-0.210921 -0.061939 -0.408022" rpy="0 0 0"/>
    <geometry>
      <mesh filename="meshes/BR_Arm1BR_motor1.stl" scale="0.001 0.001 0.001"/>
    </geometry>
  </collision>
</link>

<link name="BR_Arm1BR_Foot1">
  <inertial>
    <origin xyz="-0.010002891785989704 0.004552387674128369 -0.008935429320254873" rpy="0 0 0"/>
    <mass value="0.0032370800830491702"/>
    <inertia ixx="5.21563735275492e-07" iyy="2.398877784612818e-07" izz="4.4996323747637586e-07" ixy="-3.2027656102304874e-10" iyz="-1.3730099257246186e-07" ixz="-1.8271967654735245e-10"/>
  </inertial>
  <visual>
    <origin xyz="-0.257091 -0.079271 -0.24057" rpy="0 0 0"/>
    <geometry>
      <mesh filename="meshes/BR_Arm1BR_Foot1.stl" scale="0.001 0.001 0.001"/>
    </geometry>
    <material name="silver"/>
    <material/>
  </visual>
  <collision>
    <origin xyz="-0.257091 -0.079271 -0.24057" rpy="0 0 0"/>
    <geometry>
      <mesh filename="meshes/BR_Arm1BR_Foot1.stl" scale="0.001 0.001 0.001"/>
    </geometry>
  </collision>
</link>

<link name="BR_Arm1BR_lower_Leg1">
  <inertial>
    <origin xyz="-0.024064037426646756 0.03648490102002266 -0.03746440167106779" rpy="0 0 0"/>
    <mass value="0.0012931113059199838"/>
    <inertia ixx="3.034781363453091e-06" iyy="1.3897431509651598e-06" izz="1.8233444936497246e-06" ixy="1.1471498315824245e-07" iyz="1.4079004592478136e-06" ixz="-9.205990545011931e-08"/>
  </inertial>
  <visual>
    <origin xyz="-0.273989 0.004263 -0.321776" rpy="0 0 0"/>
    <geometry>
      <mesh filename="meshes/BR_Arm1BR_lower_Leg1.stl" scale="0.001 0.001 0.001"/>
    </geometry>
    <material name="silver"/>
    <material/>
  </visual>
  <collision>
    <origin xyz="-0.273989 0.004263 -0.321776" rpy="0 0 0"/>
    <geometry>
      <mesh filename="meshes/BR_Arm1BR_lower_Leg1.stl" scale="0.001 0.001 0.001"/>
    </geometry>
  </collision>
</link>

<link name="BR_Arm1BR_Upper_Leg1">
  <inertial>
    <origin xyz="0.01800804927169858 -0.011112605769327467 -0.014773412651875262" rpy="0 0 0"/>
    <mass value="0.0035863185548493546"/>
    <inertia ixx="4.407454092535926e-06" iyy="2.6842975551354554e-06" izz="2.847834415972212e-06" ixy="1.23530759818283e-08" iyz="-1.9578864682603508e-06" ixz="8.749586127777993e-09"/>
  </inertial>
  <visual>
    <origin xyz="-0.231887 -0.040497 -0.386579" rpy="0 0 0"/>
    <geometry>
      <mesh filename="meshes/BR_Arm1BR_Upper_Leg1.stl" scale="0.001 0.001 0.001"/>
    </geometry>
    <material name="silver"/>
    <material/>
  </visual>
  <collision>
    <origin xyz="-0.231887 -0.040497 -0.386579" rpy="0 0 0"/>
    <geometry>
      <mesh filename="meshes/BR_Arm1BR_Upper_Leg1.stl" scale="0.001 0.001 0.001"/>
    </geometry>
  </collision>
</link>

<joint name="Rev1" type="continuous">
  <origin xyz="0.111622 0.218934 0.418766" rpy="0 0 0"/>
  <parent link="base_link"/>
  <child link="FL_Arm_11FL_shoulder1"/>
  <axis xyz="-0.0 1.0 -0.0"/>
</joint>
<transmission name="Rev1_tran">
  <type>transmission_interface/SimpleTransmission</type>
  <joint name="Rev1">
    <hardwareInterface>PositionJointInterface</hardwareInterface>
  </joint>
  <actuator name="Rev1_actr">
    <hardwareInterface>PositionJointInterface</hardwareInterface>
    <mechanicalReduction>1</mechanicalReduction>
  </actuator>
</transmission>

<joint name="Rev4" type="continuous">
  <origin xyz="0.189622 0.218934 0.418766" rpy="0 0 0"/>
  <parent link="base_link"/>
  <child link="FR_Arm1FR_shoulder1"/>
  <axis xyz="-0.0 1.0 -0.0"/>
</joint>
<transmission name="Rev4_tran">
  <type>transmission_interface/SimpleTransmission</type>
  <joint name="Rev4">
    <hardwareInterface>PositionJointInterface</hardwareInterface>
  </joint>
  <actuator name="Rev4_actr">
    <hardwareInterface>PositionJointInterface</hardwareInterface>
    <mechanicalReduction>1</mechanicalReduction>
  </actuator>
</transmission>

<joint name="Rev7" type="continuous">
  <origin xyz="0.111622 0.038434 0.418767" rpy="0 0 0"/>
  <parent link="base_link"/>
  <child link="BL_Arm1BL_shoulder1"/>
  <axis xyz="-0.0 1.0 -0.0"/>
</joint>
<transmission name="Rev7_tran">
  <type>transmission_interface/SimpleTransmission</type>
  <joint name="Rev7">
    <hardwareInterface>PositionJointInterface</hardwareInterface>
  </joint>
  <actuator name="Rev7_actr">
    <hardwareInterface>PositionJointInterface</hardwareInterface>
    <mechanicalReduction>1</mechanicalReduction>
  </actuator>
</transmission>

<joint name="Rev10" type="continuous">
  <origin xyz="0.189622 0.038434 0.418767" rpy="0 0 0"/>
  <parent link="base_link"/>
  <child link="BR_Arm1BR_shoulder1"/>
  <axis xyz="-0.0 1.0 -0.0"/>
</joint>
<transmission name="Rev10_tran">
  <type>transmission_interface/SimpleTransmission</type>
  <joint name="Rev10">
    <hardwareInterface>PositionJointInterface</hardwareInterface>
  </joint>
  <actuator name="Rev10_actr">
    <hardwareInterface>PositionJointInterface</hardwareInterface>
    <mechanicalReduction>1</mechanicalReduction>
  </actuator>
</transmission>

<joint name="FL_Arm_11_Rigid1" type="fixed">
  <origin xyz="-0.020966 -0.021442 -0.021442" rpy="0 0 0"/>
  <parent link="FL_Arm_11FL_motor1"/>
  <child link="FL_Arm_11FL_Upper_Leg1"/>
</joint>

<joint name="FL_Arm_11_Rev2" type="continuous">
  <origin xyz="-0.0213 0.025755 -0.010745" rpy="0 0 0"/>
  <parent link="FL_Arm_11FL_shoulder1"/>
  <child link="FL_Arm_11FL_motor1"/>
  <axis xyz="0.999999 0.000807 0.000807"/>
</joint>
<transmission name="FL_Arm_11_Rev2_tran">
  <type>transmission_interface/SimpleTransmission</type>
  <joint name="FL_Arm_11_Rev2">
    <hardwareInterface>PositionJointInterface</hardwareInterface>
  </joint>
  <actuator name="FL_Arm_11_Rev2_actr">
    <hardwareInterface>PositionJointInterface</hardwareInterface>
    <mechanicalReduction>1</mechanicalReduction>
  </actuator>
</transmission>

<joint name="FL_Arm_11_Rigid2" type="fixed">
  <origin xyz="0.016898 0.083534 -0.081206" rpy="0 0 0"/>
  <parent link="FL_Arm_11FL_lower_Leg1"/>
  <child link="FL_Arm_11FL_Foot1"/>
</joint>

<joint name="FL_Arm_11_Rev3" type="continuous">
  <origin xyz="-0.042102 -0.04476 -0.064803" rpy="0 0 0"/>
  <parent link="FL_Arm_11FL_Upper_Leg1"/>
  <child link="FL_Arm_11FL_lower_Leg1"/>
  <axis xyz="0.999999 0.000807 0.000807"/>
</joint>
<transmission name="FL_Arm_11_Rev3_tran">
  <type>transmission_interface/SimpleTransmission</type>
  <joint name="FL_Arm_11_Rev3">
    <hardwareInterface>PositionJointInterface</hardwareInterface>
  </joint>
  <actuator name="FL_Arm_11_Rev3_actr">
    <hardwareInterface>PositionJointInterface</hardwareInterface>
    <mechanicalReduction>1</mechanicalReduction>
  </actuator>
</transmission>

<joint name="BL_Arm1_Rigid3" type="fixed">
  <origin xyz="0.016898 0.083534 -0.081206" rpy="0 0 0"/>
  <parent link="BL_Arm1BL_lower_Leg_1"/>
  <child link="BL_Arm1BL_Foot1"/>
</joint>

<joint name="BL_Arm1_Rev5" type="continuous">
  <origin xyz="-0.042103 -0.04476 -0.064803" rpy="0 0 0"/>
  <parent link="BL_Arm1BL_Upper_Leg1"/>
  <child link="BL_Arm1BL_lower_Leg_1"/>
  <axis xyz="0.999999 0.000807 0.000807"/>
</joint>
<transmission name="BL_Arm1_Rev5_tran">
  <type>transmission_interface/SimpleTransmission</type>
  <joint name="BL_Arm1_Rev5">
    <hardwareInterface>PositionJointInterface</hardwareInterface>
  </joint>
  <actuator name="BL_Arm1_Rev5_actr">
    <hardwareInterface>PositionJointInterface</hardwareInterface>
    <mechanicalReduction>1</mechanicalReduction>
  </actuator>
</transmission>

<joint name="BL_Arm1_Rigid4" type="fixed">
  <origin xyz="-0.020965 -0.021442 -0.021443" rpy="0 0 0"/>
  <parent link="BL_Arm1BL_motor1"/>
  <child link="BL_Arm1BL_Upper_Leg1"/>
</joint>

<joint name="BL_Arm1_Rev6" type="continuous">
  <origin xyz="-0.0213 0.023505 -0.010745" rpy="0 0 0"/>
  <parent link="BL_Arm1BL_shoulder1"/>
  <child link="BL_Arm1BL_motor1"/>
  <axis xyz="0.999999 0.000807 0.000807"/>
</joint>
<transmission name="BL_Arm1_Rev6_tran">
  <type>transmission_interface/SimpleTransmission</type>
  <joint name="BL_Arm1_Rev6">
    <hardwareInterface>PositionJointInterface</hardwareInterface>
  </joint>
  <actuator name="BL_Arm1_Rev6_actr">
    <hardwareInterface>PositionJointInterface</hardwareInterface>
    <mechanicalReduction>1</mechanicalReduction>
  </actuator>
</transmission>

<joint name="FR_Arm1_Rev9" type="continuous">
  <origin xyz="0.021299 0.025755 -0.010745" rpy="0 0 0"/>
  <parent link="FR_Arm1FR_shoulder1"/>
  <child link="FR_Arm1FR_motor1"/>
  <axis xyz="0.999999 -0.000807 -0.000807"/>
</joint>
<transmission name="FR_Arm1_Rev9_tran">
  <type>transmission_interface/SimpleTransmission</type>
  <joint name="FR_Arm1_Rev9">
    <hardwareInterface>PositionJointInterface</hardwareInterface>
  </joint>
  <actuator name="FR_Arm1_Rev9_actr">
    <hardwareInterface>PositionJointInterface</hardwareInterface>
    <mechanicalReduction>1</mechanicalReduction>
  </actuator>
</transmission>

<joint name="FR_Arm1_Rigid5" type="fixed">
  <origin xyz="-0.016898 0.083534 -0.081206" rpy="0 0 0"/>
  <parent link="FR_Arm1FR_lower_Leg1"/>
  <child link="FR_Arm1FR_Foot1"/>
</joint>

<joint name="FR_Arm1_Rev10" type="continuous">
  <origin xyz="0.042103 -0.04476 -0.064803" rpy="0 0 0"/>
  <parent link="FR_Arm1FR_Upper_Leg1"/>
  <child link="FR_Arm1FR_lower_Leg1"/>
  <axis xyz="0.999999 -0.000807 -0.000807"/>
</joint>
<transmission name="FR_Arm1_Rev10_tran">
  <type>transmission_interface/SimpleTransmission</type>
  <joint name="FR_Arm1_Rev10">
    <hardwareInterface>PositionJointInterface</hardwareInterface>
  </joint>
  <actuator name="FR_Arm1_Rev10_actr">
    <hardwareInterface>PositionJointInterface</hardwareInterface>
    <mechanicalReduction>1</mechanicalReduction>
  </actuator>
</transmission>

<joint name="FR_Arm1_Rigid6" type="fixed">
  <origin xyz="0.020965 -0.021442 -0.021442" rpy="0 0 0"/>
  <parent link="FR_Arm1FR_motor1"/>
  <child link="FR_Arm1FR_Upper_Leg1"/>
</joint>

<joint name="BR_Arm1_Rev11" type="continuous">
  <origin xyz="0.021299 0.023505 -0.010745" rpy="0 0 0"/>
  <parent link="BR_Arm1BR_shoulder1"/>
  <child link="BR_Arm1BR_motor1"/>
  <axis xyz="0.999999 -0.000807 -0.000807"/>
</joint>
<transmission name="BR_Arm1_Rev11_tran">
  <type>transmission_interface/SimpleTransmission</type>
  <joint name="BR_Arm1_Rev11">
    <hardwareInterface>PositionJointInterface</hardwareInterface>
  </joint>
  <actuator name="BR_Arm1_Rev11_actr">
    <hardwareInterface>PositionJointInterface</hardwareInterface>
    <mechanicalReduction>1</mechanicalReduction>
  </actuator>
</transmission>

<joint name="BR_Arm1_Rigid7" type="fixed">
  <origin xyz="-0.016898 0.083534 -0.081206" rpy="0 0 0"/>
  <parent link="BR_Arm1BR_lower_Leg1"/>
  <child link="BR_Arm1BR_Foot1"/>
</joint>

<joint name="BR_Arm1_Rev12" type="continuous">
  <origin xyz="0.042102 -0.04476 -0.064803" rpy="0 0 0"/>
  <parent link="BR_Arm1BR_Upper_Leg1"/>
  <child link="BR_Arm1BR_lower_Leg1"/>
  <axis xyz="0.999999 -0.000807 -0.000807"/>
</joint>
<transmission name="BR_Arm1_Rev12_tran">
  <type>transmission_interface/SimpleTransmission</type>
  <joint name="BR_Arm1_Rev12">
    <hardwareInterface>PositionJointInterface</hardwareInterface>
  </joint>
  <actuator name="BR_Arm1_Rev12_actr">
    <hardwareInterface>PositionJointInterface</hardwareInterface>
    <mechanicalReduction>1</mechanicalReduction>
  </actuator>
</transmission>

<joint name="BR_Arm1_Rigid8" type="fixed">
  <origin xyz="0.020966 -0.021442 -0.021443" rpy="0 0 0"/>
  <parent link="BR_Arm1BR_motor1"/>
  <child link="BR_Arm1BR_Upper_Leg1"/>
</joint>

</robot>
